try{
 foo();
} catch(er)
{
  console.log("Caught an error");
}
